<mujoco model="k-bot_sim">

  <compiler angle="radian"  meshdir="meshes"/>

  <default>
    <default class="robot">
      <default class="motor_00">
        <joint armature="0.0005" frictionloss="0.1" actuatorfrcrange="-20.0 20.0" />
        <motor ctrlrange="-20.0 20.0" />
      </default>
      <default class="motor_02">
        <joint armature="0.0015" frictionloss="0.1" actuatorfrcrange="-30.0 30.0" />
        <motor ctrlrange="-30.0 30.0" />
      </default>
      <default class="motor_03">
        <joint armature="0.005" frictionloss="0.001" actuatorfrcrange="-100.0 100.0" />
        <motor ctrlrange="-100.0 100.0" />
      </default>
      <default class="motor_04">
        <joint armature="0.007" frictionloss="0.0015" actuatorfrcrange="-200.0 200.0" />
        <motor ctrlrange="-200.0 200.0" />
      </default>
      <default class="visual">
        <geom material="visualgeom" contype="0" conaffinity="0" group="2" />
      </default>
      <default class="collision">
        <geom condim="6" friction="0.8 0.02 0.01" group="3" />
      </default>
    </default>
  </default>

  <asset>
    <mesh name="body1-part.collision" file="body1-part.collision.stl"/>
    <mesh name="shoulder.collision" file="shoulder.collision.stl"/>
    <mesh name="shoulder_2.collision" file="shoulder_2.collision.stl"/>
    <mesh name="leg0_shell.collision" file="leg0_shell.collision.stl"/>
    <mesh name="leg0_shell_2.collision" file="leg0_shell_2.collision.stl"/>
    <mesh name="arm2_shell.collision" file="arm2_shell.collision.stl"/>
    <mesh name="arm2_shell_2.collision" file="arm2_shell_2.collision.stl"/>
    <mesh name="hand_shell.collision" file="hand_shell.collision.stl"/>
    <mesh name="hand_shell_2.collision" file="hand_shell_2.collision.stl"/>
    <mesh name="leg3_shell1.collision" file="leg3_shell1.collision.stl"/>
    <mesh name="leg3_shell11.collision" file="leg3_shell11.collision.stl"/>
    <mesh name="foot3.collision" file="foot3.collision.stl"/>
    <mesh name="foot1.collision" file="foot1.collision.stl"/>
  </asset>

  <worldbody>
    <body name="root" pos="0 0 0" quat="1 0 0 0">
      <camera name="tracking_camera" mode="track" pos="0.0 -2.0 1.0" quat="0.7071 0.3827 0.0 0.0" fovy="90.0" />
        <freejoint name="floating_base" />
        <site name="imu_site" size="0.01" pos="0.039989396 -0.12791044000000001 -2.6794896579307448e-11"/>
        <body name="body1-part" quat="0.000563312 0.000562864 0.706825 0.707388">
        <inertial pos="-0.000194676 -0.209193 -6.5933e-05" quat="0.707026 0.707186 0.000991344 0.000198047" mass="16.5406" diaginertia="1.14646 0.609236 0.557347"/>
        <geom name="body1-part.collision" type="mesh" rgba="1 1 1 1" mesh="body1-part.collision"/>
        <geom name="shoulder.collision" pos="-1.1e-05 0.01809 0.1885" quat="0 -1.73205e-07 1 -1.73205e-07" type="mesh" rgba="1 1 1 1" mesh="shoulder.collision"/>
        <geom name="arm2_shell.collision" pos="-2.29054e-05 -0.122354 0.256" quat="-0.5 0.5 0.5 0.5" type="mesh" rgba="0.898039 0.917647 0.929412 1" mesh="arm2_shell.collision"/>
        <geom name="hand_shell.collision" pos="-2.26306e-05 -0.402854 0.2505" quat="0.707107 -0.707107 -7.07107e-07 2.31079e-07" type="mesh" rgba="0.898039 0.917647 0.929412 1" mesh="hand_shell.collision"/>
        <geom name="shoulder.collision_2" pos="-1.1e-05 0.01809 -0.1885" quat="-1.73205e-07 0 0 -1" type="mesh" rgba="1 1 1 1" mesh="shoulder_2.collision"/>
        <geom name="arm2_shell.collision_2" pos="-0.001023 -0.122354 -0.256" quat="-6.93502e-09 2.38014e-07 0.707107 -0.707107" type="mesh" rgba="0.898039 0.917647 0.929412 1" mesh="arm2_shell_2.collision"/>
        <geom name="hand_shell.collision_2" pos="-0.00102305 -0.402354 -0.2505" quat="-0.707107 0.707107 1.08605e-07 -1.08604e-07" type="mesh" rgba="0.898039 0.917647 0.929412 1" mesh="hand_shell_2.collision"/>
        <body name="leg0_shell" pos="-1.1e-05 -0.43201 0.0887" quat="0 1.73205e-07 1 1.73205e-07">
            <inertial pos="-0.003746 0 -0.068125" quat="0.999982 0 -0.00597152 0" mass="1.32345" diaginertia="0.00188608 0.001425 0.00129992"/>
            <joint name="left_hip_pitch_04" type="hinge" class="motor_04" pos="0 0 0" axis="0 0 1" range="-1.5708 1.5708"/>
            <geom name="leg0_shell.collision" type="mesh" rgba="0.898039 0.917647 0.929412 1" mesh="leg0_shell.collision"/>
            <body name="leg1_shell" pos="0.0275 0 -0.0695" quat="0.5 -0.5 -0.5 0.5">
            <inertial pos="-0.112524 0.000529 0.025259" quat="-0.149163 0.776513 -0.185318 0.583469" mass="1.26435" diaginertia="0.00249944 0.00248268 0.00139787"/>
            <joint name="left_hip_roll_03" type="hinge" class="motor_03" pos="0 0 0" axis="0 0 1" range="-3.18523 0.349066"/>
            <body name="leg2_shell" pos="-0.1575 0.00012 0.0275" quat="0.707107 0 0.707107 0">
                <inertial pos="0 0.000532 -0.137308" quat="0.707085 -0.00556072 0.00556072 0.707085" mass="1.82092" diaginertia="0.00422553 0.003118 0.00206347"/>
                <joint name="left_hip_yaw_03" type="hinge" class="motor_03" pos="0 0 0" axis="0 0 1" range="-1.5708 1.5708" />
                <body name="leg3_shell1" pos="0 -0.027 -0.1425" quat="0.707107 0.707107 0 0">
                <inertial pos="0.001098 -0.131322 -0.023162" quat="0.29298 0.299254 -0.639764 0.644447" mass="1.10996" diaginertia="0.00676042 0.00672628 0.0010123"/>
                <joint name="left_knee_04" type="hinge" class="motor_04" pos="0 0 0" axis="0 0 -1" range="0 2.0944"/>
                <geom name="leg3_shell1.collision" type="mesh" rgba="0.898039 0.917647 0.929412 1" mesh="leg3_shell1.collision"/>
                <body name="foot1" pos="0 -0.3 0.0095">
                    <inertial pos="0.02135 -0.019419 -0.019276" quat="0.504954 0.505314 0.484937 0.504496" mass="0.582091" diaginertia="0.00218891 0.00202456 0.000282532"/>
                    <joint name="left_ankle_02" type="hinge" class="motor_02" pos="0 0 0" axis="0 0 -1" range="-0.698132 0.698132"/>
                    <geom name="foot1.collision" type="mesh" rgba="0.898039 0.917647 0.929412 1" mesh="foot1.collision"/>
                </body>
                </body>
            </body>
            </body>
        </body>
        <body name="leg0_shell_2" pos="-1.1e-05 -0.43201 -0.0892" quat="-1.73205e-07 0 0 -1">
            <inertial pos="-0.003746 0 -0.067625" quat="0.999982 0 -0.00597152 0" mass="1.32345" diaginertia="0.00188608 0.001425 0.00129992"/>
            <joint name="right_hip_pitch_04" type="hinge" class="motor_04" pos="0 0 0" axis="0 0 1" range="-1.5708 1.5708"/>
            <geom name="leg0_shell.collision_2" type="mesh" rgba="0.898039 0.917647 0.929412 1" mesh="leg0_shell_2.collision"/>
            <body name="leg1_shell3" pos="0.0275 0 -0.069" quat="0.5 0.5 -0.5 -0.5">
            <inertial pos="-0.112524 -0.000529 0.025259" quat="0.149163 0.776513 0.185318 0.583469" mass="1.26435" diaginertia="0.00249944 0.00248268 0.00139787"/>
            <joint name="right_hip_roll_03" type="hinge" class="motor_03" pos="0 0 0" axis="0 0 1" range="-0.349066 3.18523"/>
            <body name="leg2_shell_2" pos="-0.1575 -0.00012 0.0275" quat="-1.22475e-07 -0.707107 1.22474e-07 -0.707107">
                <inertial pos="0 0.000532 -0.137308" quat="0.707085 -0.00556072 0.00556072 0.707085" mass="1.82092" diaginertia="0.00422553 0.003118 0.00206347"/>
                <joint name="right_hip_yaw_03" type="hinge" class="motor_03" pos="0 0 0" axis="0 0 1" range="-1.5708 1.5708"/>
                <body name="leg3_shell11" pos="0 -0.027 -0.1425" quat="0.707107 0.707107 0 0">
                <inertial pos="-0.001098 -0.131322 -0.023162" quat="0.644447 0.639764 -0.299254 0.29298" mass="1.10996" diaginertia="0.00676042 0.00672628 0.0010123"/>
                <joint name="right_knee_04" type="hinge" class="motor_04" pos="0 0 0" axis="0 0 -1" range="-2.0944 0"/>
                <geom name="leg3_shell11.collision" type="mesh" rgba="0.898039 0.917647 0.929412 1" mesh="leg3_shell11.collision"/>
                <body name="foot3" pos="0 -0.3 -0.0355" quat="0 -1.73205e-07 1 -1.73205e-07">
                    <inertial pos="0.02135 -0.019419 -0.023724" quat="0.505314 0.504954 0.504496 0.484937" mass="0.582091" diaginertia="0.00218891 0.00202456 0.000282532"/>
                    <joint name="right_ankle_02" type="hinge" class="motor_02"  pos="0 0 0" axis="0 0 1" range="-0.698132 0.698132" />
                    <geom name="foot3.collision" type="mesh" rgba="0.898039 0.917647 0.929412 1" mesh="foot3.collision"/>
                </body>
                </body>
            </body>
            </body>
        </body>
        </body>
    </body>
  </worldbody>

  <actuator>
    <motor name="left_hip_pitch_04_ctrl" joint="left_hip_pitch_04" class="motor_04" />
    <motor name="left_hip_roll_03_ctrl" joint="left_hip_roll_03" class="motor_03" />
    <motor name="left_hip_yaw_03_ctrl" joint="left_hip_yaw_03" class="motor_03" />
    <motor name="left_knee_04_ctrl" joint="left_knee_04" class="motor_04" />
    <motor name="left_ankle_02_ctrl" joint="left_ankle_02" class="motor_02" />
    <motor name="right_hip_pitch_04_ctrl" joint="right_hip_pitch_04" class="motor_04" />
    <motor name="right_hip_roll_03_ctrl" joint="right_hip_roll_03" class="motor_03" />
    <motor name="right_hip_yaw_03_ctrl" joint="right_hip_yaw_03" class="motor_03" />
    <motor name="right_knee_04_ctrl" joint="right_knee_04" class="motor_04" />
    <motor name="right_ankle_02_ctrl" joint="right_ankle_02" class="motor_02" />
  
  </actuator>

  <sensor>
    <accelerometer name="imu_acc" site="imu_site" noise="0.01" />
    <gyro name="imu_gyro" site="imu_site" noise="0.01" />
    <magnetometer name="imu_mag" site="imu_site" noise="0.05" />
    <framepos name="base_link_pos" objtype="site" objname="imu_site" />
    <framequat name="base_link_quat" objtype="site" objname="imu_site" />
    <framelinvel name="base_link_vel" objtype="site" objname="imu_site" />
    <frameangvel name="base_link_ang_vel" objtype="site" objname="imu_site" />
  </sensor>
    <keyframe>
    <key name="default" qpos="0 0 1.05 0. 0.0 0.0 1.0 0.23 0.0 0.0 0.441 -0.195 -0.23 0.0 0.0 -0.441 0.195"/>
    <key name="standing" qpos="0 0 1.075 0. 0.0 0.0 1.0 0 0.0 0.0 0 0 0 0.0 0.0 0 0"/>
  </keyframe>
</mujoco>
